<?xml version="1.0" encoding="UTF-8"?>
<testng-results ignored="0" total="3" passed="1" failed="2" skipped="0">
  <reporter-output>
  </reporter-output>
  <suite started-at="2021-03-18T18:05:29 EDT" name="Default suite" finished-at="2021-03-18T18:05:39 EDT" duration-ms="10076">
    <groups>
    </groups>
    <test started-at="2021-03-18T18:05:29 EDT" name="Default test" finished-at="2021-03-18T18:05:39 EDT" duration-ms="10076">
      <class name="day31.DataProviderDemo">
        <test-method is-config="true" signature="setup()[pri:0, instance:day31.DataProviderDemo@2cd2a21f]" started-at="2021-03-18T18:05:29 EDT" name="setup" finished-at="2021-03-18T18:05:31 EDT" duration-ms="2314" status="PASS">
          <reporter-output>
          </reporter-output>
        </test-method> <!-- setup -->
        <test-method signature="test_login1(java.lang.String, java.lang.String, java.lang.String)[pri:0, instance:day31.DataProviderDemo@2cd2a21f]" started-at="2021-03-18T18:05:31 EDT" name="test_login1" data-provider="dp1" finished-at="2021-03-18T18:05:35 EDT" duration-ms="4152" status="PASS">
          <params>
            <param index="0">
              <value>
                <![CDATA[test123@gmail.com]]>
              </value>
            </param>
            <param index="1">
              <value>
                <![CDATA[test123]]>
              </value>
            </param>
            <param index="2">
              <value>
                <![CDATA[nopCommerce demo store]]>
              </value>
            </param>
          </params>
          <reporter-output>
          </reporter-output>
        </test-method> <!-- test_login1 -->
        <test-method signature="test_login1(java.lang.String, java.lang.String, java.lang.String)[pri:0, instance:day31.DataProviderDemo@2cd2a21f]" started-at="2021-03-18T18:05:35 EDT" name="test_login1" data-provider="dp1" finished-at="2021-03-18T18:05:37 EDT" duration-ms="2327" status="FAIL">
          <params>
            <param index="0">
              <value>
                <![CDATA[test@gmail.com]]>
              </value>
            </param>
            <param index="1">
              <value>
                <![CDATA[test3]]>
              </value>
            </param>
            <param index="2">
              <value>
                <![CDATA[nopCommerce demo store]]>
              </value>
            </param>
          </params>
          <exception class="java.lang.AssertionError">
            <message>
              <![CDATA[expected [nopCommerce demo store. Login] but found [nopCommerce demo store]]]>
            </message>
            <full-stacktrace>
              <![CDATA[java.lang.AssertionError: expected [nopCommerce demo store. Login] but found [nopCommerce demo store]
at org.testng.Assert.fail(Assert.java:99)
at org.testng.Assert.failNotEquals(Assert.java:1037)
at org.testng.Assert.assertEqualsImpl(Assert.java:140)
at org.testng.Assert.assertEquals(Assert.java:122)
at org.testng.Assert.assertEquals(Assert.java:629)
at org.testng.Assert.assertEquals(Assert.java:639)
at day31.DataProviderDemo.test_login1(DataProviderDemo.java:32)
at java.base/jdk.internal.reflect.NativeMethodAccessorImpl.invoke0(Native Method)
at java.base/jdk.internal.reflect.NativeMethodAccessorImpl.invoke(NativeMethodAccessorImpl.java:62)
at java.base/jdk.internal.reflect.DelegatingMethodAccessorImpl.invoke(DelegatingMethodAccessorImpl.java:43)
at java.base/java.lang.reflect.Method.invoke(Method.java:566)
at org.testng.internal.MethodInvocationHelper.invokeMethod(MethodInvocationHelper.java:132)
at org.testng.internal.TestInvoker.invokeMethod(TestInvoker.java:599)
at org.testng.internal.TestInvoker.invokeTestMethod(TestInvoker.java:174)
at org.testng.internal.MethodRunner.runInSequence(MethodRunner.java:46)
at org.testng.internal.TestInvoker$MethodInvocationAgent.invoke(TestInvoker.java:822)
at org.testng.internal.TestInvoker.invokeTestMethods(TestInvoker.java:147)
at org.testng.internal.TestMethodWorker.invokeTestMethods(TestMethodWorker.java:146)
at org.testng.internal.TestMethodWorker.run(TestMethodWorker.java:128)
at java.base/java.util.ArrayList.forEach(ArrayList.java:1540)
at org.testng.TestRunner.privateRun(TestRunner.java:764)
at org.testng.TestRunner.run(TestRunner.java:585)
at org.testng.SuiteRunner.runTest(SuiteRunner.java:384)
at org.testng.SuiteRunner.runSequentially(SuiteRunner.java:378)
at org.testng.SuiteRunner.privateRun(SuiteRunner.java:337)
at org.testng.SuiteRunner.run(SuiteRunner.java:286)
at org.testng.SuiteRunnerWorker.runSuite(SuiteRunnerWorker.java:53)
at org.testng.SuiteRunnerWorker.run(SuiteRunnerWorker.java:96)
at org.testng.TestNG.runSuitesSequentially(TestNG.java:1218)
at org.testng.TestNG.runSuitesLocally(TestNG.java:1140)
at org.testng.TestNG.runSuites(TestNG.java:1069)
at org.testng.TestNG.run(TestNG.java:1037)
at org.testng.remote.AbstractRemoteTestNG.run(AbstractRemoteTestNG.java:115)
at org.testng.remote.RemoteTestNG.initAndRun(RemoteTestNG.java:251)
at org.testng.remote.RemoteTestNG.main(RemoteTestNG.java:77)
]]>
            </full-stacktrace>
          </exception> <!-- java.lang.AssertionError -->
          <reporter-output>
          </reporter-output>
        </test-method> <!-- test_login1 -->
        <test-method signature="test_login1(java.lang.String, java.lang.String, java.lang.String)[pri:0, instance:day31.DataProviderDemo@2cd2a21f]" started-at="2021-03-18T18:05:37 EDT" name="test_login1" data-provider="dp1" finished-at="2021-03-18T18:05:38 EDT" duration-ms="1041" status="FAIL">
          <params>
            <param index="0">
              <value>
                <![CDATA[t@gmail.com]]>
              </value>
            </param>
            <param index="1">
              <value>
                <![CDATA[t23]]>
              </value>
            </param>
            <param index="2">
              <value>
                <![CDATA[nopCommerce demo store]]>
              </value>
            </param>
          </params>
          <exception class="java.lang.AssertionError">
            <message>
              <![CDATA[expected [nopCommerce demo store. Login] but found [nopCommerce demo store]]]>
            </message>
            <full-stacktrace>
              <![CDATA[java.lang.AssertionError: expected [nopCommerce demo store. Login] but found [nopCommerce demo store]
at org.testng.Assert.fail(Assert.java:99)
at org.testng.Assert.failNotEquals(Assert.java:1037)
at org.testng.Assert.assertEqualsImpl(Assert.java:140)
at org.testng.Assert.assertEquals(Assert.java:122)
at org.testng.Assert.assertEquals(Assert.java:629)
at org.testng.Assert.assertEquals(Assert.java:639)
at day31.DataProviderDemo.test_login1(DataProviderDemo.java:32)
at java.base/jdk.internal.reflect.NativeMethodAccessorImpl.invoke0(Native Method)
at java.base/jdk.internal.reflect.NativeMethodAccessorImpl.invoke(NativeMethodAccessorImpl.java:62)
at java.base/jdk.internal.reflect.DelegatingMethodAccessorImpl.invoke(DelegatingMethodAccessorImpl.java:43)
at java.base/java.lang.reflect.Method.invoke(Method.java:566)
at org.testng.internal.MethodInvocationHelper.invokeMethod(MethodInvocationHelper.java:132)
at org.testng.internal.TestInvoker.invokeMethod(TestInvoker.java:599)
at org.testng.internal.TestInvoker.invokeTestMethod(TestInvoker.java:174)
at org.testng.internal.MethodRunner.runInSequence(MethodRunner.java:46)
at org.testng.internal.TestInvoker$MethodInvocationAgent.invoke(TestInvoker.java:822)
at org.testng.internal.TestInvoker.invokeTestMethods(TestInvoker.java:147)
at org.testng.internal.TestMethodWorker.invokeTestMethods(TestMethodWorker.java:146)
at org.testng.internal.TestMethodWorker.run(TestMethodWorker.java:128)
at java.base/java.util.ArrayList.forEach(ArrayList.java:1540)
at org.testng.TestRunner.privateRun(TestRunner.java:764)
at org.testng.TestRunner.run(TestRunner.java:585)
at org.testng.SuiteRunner.runTest(SuiteRunner.java:384)
at org.testng.SuiteRunner.runSequentially(SuiteRunner.java:378)
at org.testng.SuiteRunner.privateRun(SuiteRunner.java:337)
at org.testng.SuiteRunner.run(SuiteRunner.java:286)
at org.testng.SuiteRunnerWorker.runSuite(SuiteRunnerWorker.java:53)
at org.testng.SuiteRunnerWorker.run(SuiteRunnerWorker.java:96)
at org.testng.TestNG.runSuitesSequentially(TestNG.java:1218)
at org.testng.TestNG.runSuitesLocally(TestNG.java:1140)
at org.testng.TestNG.runSuites(TestNG.java:1069)
at org.testng.TestNG.run(TestNG.java:1037)
at org.testng.remote.AbstractRemoteTestNG.run(AbstractRemoteTestNG.java:115)
at org.testng.remote.RemoteTestNG.initAndRun(RemoteTestNG.java:251)
at org.testng.remote.RemoteTestNG.main(RemoteTestNG.java:77)
]]>
            </full-stacktrace>
          </exception> <!-- java.lang.AssertionError -->
          <reporter-output>
          </reporter-output>
        </test-method> <!-- test_login1 -->
        <test-method is-config="true" signature="tearDown()[pri:0, instance:day31.DataProviderDemo@2cd2a21f]" started-at="2021-03-18T18:05:38 EDT" name="tearDown" finished-at="2021-03-18T18:05:39 EDT" duration-ms="138" status="PASS">
          <reporter-output>
          </reporter-output>
        </test-method> <!-- tearDown -->
      </class> <!-- day31.DataProviderDemo -->
    </test> <!-- Default test -->
  </suite> <!-- Default suite -->
</testng-results>
